Workbook

Sheet General Summary
A1: GENERAL SUMMARY (BASE BID)
A2: DIVISION NO. | B2: DESCRIPTION | C2: TOTAL DIV. COST
A3: 1000 | B3: General Requirments | C3: ='Base Bid'!Q15 -> 184000
A4: 26000 | B4: Electrical | C4: ='Base Bid'!Q277 -> 2090736.7
A5: 26000 | B5: Telecommunication | C5: ='Base Bid'!Q376 -> 295042.39
A6: 26000 | B6: Electronic & Safety Security | C6: ='Base Bid'!Q453 -> 251546.67
A7: TOTAL COST | C7: =SUM(C3:C6) -> 2821325.7
A9: CONTIGENCIES (5%) | B9: 0.05 | C9: =C7*B9 -> 141066.29
A10: MATERIAL MARKUPS (20%) | B10: 0.2 | C10: =B10*SUM('Base Bid'!O17:O454) -> 312193.46
A11: LABOR MARKUPS (31%) | B11: 0.31 | C11: =B11*SUM('Base Bid'!M17:M454) -> 333671.12
A12: OVERHEAD (10%) | B12: 0.1 | C12: =C7*B12 -> 282132.57
A13: PROFIT (10%) | B13: 0.1 | C13: =C7*B13 -> 282132.57
A14: TAX (9.2%) | B14: 0.092 | C14: =C7*B14 -> 259561.97
A15: PERFORMANCE AND PAYMENT BONDS | B15: 0.015 | C15: =C7*B15 -> 42319.886
A16: TOTAL BASEBID | C16: =SUM(C7,C9:C15) -> 4474403.6
A18: GENERAL SUMMARY (ADD ALTERNATE)
A19: DIVISION NO. | B19: DESCRIPTION | C19: TOTAL DIV. COST
A20: 1000 | B20: General Requirments | C20: ='Add Alternate'!Q15 -> 1500
A21: 26000 | B21: Pedestrain Gate Card Reader | C21: ='Add Alternate'!Q46 -> 10338.246
A22: TOTAL COST | C22: =SUM(C20:C21) -> 11838.246
A24: CONTIGENCIES (5%) | B24: 0.05 | C24: =C22*B24 -> 591.9123
A25: MATERIAL MARKUPS (20%) | B25: 0.2 | C25: =B25*SUM('Add Alternate'!O17:O46) -> 639.9293
A26: LABOR MARKUPS (31%) | B26: 0.31 | C26: =B26*SUM('Add Alternate'!M17:M46) -> 2212.9659
A27: OVERHEAD (10%) | B27: 0.1 | C27: =C22*B27 -> 1183.8246
A28: PROFIT (10%) | B28: 0.1 | C28: =C22*B28 -> 1183.8246
A29: TAX (9.2%) | B29: 0.092 | C29: =C22*B29 -> 1089.1186
A30: PERFORMANCE AND PAYMENT BONDS | B30: 0.015 | C30: =C22*B30 -> 177.57369
A31: TOTAL BASEBID | C31: =SUM(C22,C24:C30) -> 18917.395

Sheet Base Bid
A2: DETAILED BREAKDOWN OF ITEMS
B3: Project Name | D3: Joint Public Safety Facility
B4: Project Address | D4: 2100 w edgewood dr. port angeles, wa 98363
B5: Scope: | D5: Electrical
A6: S# | B6: Dwg. | C6: CSI NO | D6: DESCRIPTION | E6: QTY. | F6: Wastage | G6: Qty w/ Waste | H6: UNIT | I6: UNIT LABOR HOUR | J6: TOTAL LABOR HOUR | K6: LABOR WAGE/ HOUR | L6: UNIT LABOR COST | M6: TOTAL LABOR COST | N6: UNIT MATERIAL COST | O6: TOTAL MATERIAL COST | P6: UNIT PRICE (Labor & Material) | Q6: TRADE TOTAL
C7: 1 | D7: DIVISION 01-GENERAL REQUIREMENTS
A8: =IF(F8<>"",1+MAX($A$2:A7),"") -> 1 | D8: Permits | E8: 1 | F8: 0 | G8: =(F8*E8)+E8 -> 1 | H8: LS | I8: 0 | J8: =+I8*G8 -> 0 | K8: 0 | L8: =I8*K8 -> 0 | M8: =K8*J8 -> 0 | N8: 0 | O8: =N8*G8 -> 0 | P8: =(I8*K8)+N8 -> 0 | Q8: 184000
A9: =IF(F9<>"",1+MAX($A$2:A8),"") -> 2 | D9: Supervision and Coordination | E9: 1 | F9: 0 | G9: =(F9*E9)+E9 -> 1 | H9: LS | I9: 0 | J9: =+I9*G9 -> 0 | K9: 0 | L9: =I9*K9 -> 0 | M9: =K9*J9 -> 0 | N9: 0 | O9: =N9*G9 -> 0 | P9: =(I9*K9)+N9 -> 0
A10: =IF(F10<>"",1+MAX($A$2:A9),"") -> 3 | D10: Submittals and Shop drawings | E10: 1 | F10: 0 | G10: =(F10*E10)+E10 -> 1 | H10: LS | I10: 0 | J10: =+I10*G10 -> 0 | K10: 0 | L10: =I10*K10 -> 0 | M10: =K10*J10 -> 0 | N10: 0 | O10: =N10*G10 -> 0 | P10: =(I10*K10)+N10 -> 0
A11: =IF(F11<>"",1+MAX($A$2:A10),"") -> 4 | D11: Final Cleaning | E11: 1 | F11: 0 | G11: =(F11*E11)+E11 -> 1 | H11: LS | I11: 0 | J11: =+I11*G11 -> 0 | K11: 0 | L11: =I11*K11 -> 0 | M11: =K11*J11 -> 0 | N11: 0 | O11: =N11*G11 -> 0 | P11: =(I11*K11)+N11 -> 0
A12: =IF(F12<>"",1+MAX($A$2:A11),"") -> 5 | D12: Mobilization Costs | E12: 1 | F12: 0 | G12: =(F12*E12)+E12 -> 1 | H12: LS | I12: 0 | J12: =+I12*G12 -> 0 | K12: 0 | L12: =I12*K12 -> 0 | M12: =K12*J12 -> 0 | N12: 0 | O12: =N12*G12 -> 0 | P12: =(I12*K12)+N12 -> 0
A13: =IF(F13<>"",1+MAX($A$2:A12),"") -> 6 | D13: Temporary Control & Facilities | E13: 1 | F13: 0 | G13: =(F13*E13)+E13 -> 1 | H13: LS | I13: 0 | J13: =+I13*G13 -> 0 | K13: 0 | L13: =I13*K13 -> 0 | M13: =K13*J13 -> 0 | N13: 0 | O13: =N13*G13 -> 0 | P13: =(I13*K13)+N13 -> 0
A14: =IF(F14<>"",1+MAX($A$2:A13),"") -> 7 | D14: Scaffolding | E14: 1 | F14: 0 | G14: =(F14*E14)+E14 -> 1 | H14: LS | I14: 0 | J14: =+I14*G14 -> 0 | K14: 0 | L14: =I14*K14 -> 0 | M14: =K14*J14 -> 0 | N14: 0 | O14: =N14*G14 -> 0 | P14: =(I14*K14)+N14 -> 0
A15: =IF(F15<>"",1+MAX($A$2:A14),"") | D15: SUBTOTAL | Q15: =SUM(Q8:Q14) -> 184000
A16: =IF(F16<>"",1+MAX($A$2:A15),"")
A17: =IF(F17<>"",1+MAX($A$2:A16),"") | C17: 26 | D17: DIVISION 26- ELECTRICAL
A18: =IF(F18<>"",1+MAX($A$2:A17),"") | D18: DISTRIBUTION
A19: =IF(F19<>"",1+MAX($A$2:A18),"") | D19: FEEDERS
A20: =IF(F20<>"",1+MAX($A$2:A19),"") | D20: CONDUITS
A21: =IF(F21<>"",1+MAX($A$2:A20),"") -> 8 | D21: 4"C EMT | E21: 169.8 | F21: 0.05 | G21: =(F21*E21)+E21 -> 178.29 | H21: LF | I21: 0.146 | J21: =+I21*G21 -> 26.03034 | K21: ='LABOR SHEET'!C$3 -> 128 | L21: =I21*K21 -> 18.688 | M21: =K21*J21 -> 3331.8835 | N21: =138.78/10+1 -> 14.878 | O21: =N21*G21 -> 2652.5986 | P21: =(I21*K21)+N21 -> 33.566 | Q21: =P21*G21 -> 5984.4821
A22: =IF(F22<>"",1+MAX($A$2:A21),"") -> 9 | D22: 4"C PVC | E22: 3840.06 | F22: 0.05 | G22: =(F22*E22)+E22 -> 4032.063 | H22: LF | I22: 0.115 | J22: =+I22*G22 -> 463.68725 | K22: ='LABOR SHEET'!C$3 -> 128 | L22: =I22*K22 -> 14.72 | M22: =K22*J22 -> 59351.967 | N22: 9.27 | O22: =N22*G22 -> 37377.224 | P22: =(I22*K22)+N22 -> 23.99 | Q22: =P22*G22 -> 96729.191
A23: =IF(F23<>"",1+MAX($A$2:A22),"") -> 10 | D23: 3"C EMT | E23: 1079.76 | F23: 0.05 | G23: =(F23*E23)+E23 -> 1133.748 | H23: LF | I23: 0.138 | J23: =+I23*G23 -> 156.45722 | K23: ='LABOR SHEET'!C$3 -> 128 | L23: =I23*K23 -> 17.664 | M23: =K23*J23 -> 20026.525 | N23: =103.68/10+0.85 -> 11.218 | O23: =N23*G23 -> 12718.385 | P23: =(I23*K23)+N23 -> 28.882 | Q23: =P23*G23 -> 32744.91
A24: =IF(F24<>"",1+MAX($A$2:A23),"") -> 11 | D24: 2"C EMT | E24: 234.75 | F24: 0.05 | G24: =(F24*E24)+E24 -> 246.4875 | H24: LF | I24: 0.11 | J24: =+I24*G24 -> 27.113625 | K24: ='LABOR SHEET'!C$3 -> 128 | L24: =I24*K24 -> 14.08 | M24: =K24*J24 -> 3470.544 | N24: =40.48/10+0.55 -> 4.598 | O24: =N24*G24 -> 1133.3495 | P24: =(I24*K24)+N24 -> 18.678 | Q24: =P24*G24 -> 4603.8935
A25: =IF(F25<>"",1+MAX($A$2:A24),"") -> 12 | D25: 1 1/2"C EMT | E25: 601.29 | F25: 0.05 | G25: =(F25*E25)+E25 -> 631.3545 | H25: LF | I25: 0.1 | J25: =+I25*G25 -> 63.13545 | K25: ='LABOR SHEET'!C$3 -> 128 | L25: =I25*K25 -> 12.8 | M25: =K25*J25 -> 8081.3376 | N25: =34/10+0.35 -> 3.75 | O25: =N25*G25 -> 2367.5794 | P25: =(I25*K25)+N25 -> 16.55 | Q25: =P25*G25 -> 10448.917
A26: =IF(F26<>"",1+MAX($A$2:A25),"") -> 13 | D26: PULLSTRING | E26: 3357.45 | F26: 0.05 | G26: =(F26*E26)+E26 -> 3525.3225 | H26: LF | I26: 0.01 | J26: =+I26*G26 -> 35.253225 | K26: ='LABOR SHEET'!C$3 -> 128 | L26: =I26*K26 -> 1.28 | M26: =K26*J26 -> 4512.4128 | N26: 0.35 | O26: =N26*G26 -> 1233.8629 | P26: =(I26*K26)+N26 -> 1.63 | Q26: =P26*G26 -> 5746.2757
A27: =IF(F27<>"",1+MAX($A$2:A26),"")
A28: =IF(F28<>"",1+MAX($A$2:A27),"") | D28: CONDUTORS
A29: =IF(F29<>"",1+MAX($A$2:A28),"") -> 14 | D29: #600 THHN | E29: 3548.64 | F29: 0.05 | G29: =(F29*E29)+E29 -> 3726.072 | H29: LF | I29: 0.1 | J29: =+I29*G29 -> 372.6072 | K29: ='LABOR SHEET'!C$3 -> 128 | L29: =I29*K29 -> 12.8 | M29: =K29*J29 -> 47693.722 | N29: 22.57 | O29: =N29*G29 -> 84097.445 | P29: =(I29*K29)+N29 -> 35.37 | Q29: =P29*G29 -> 131791.17
A30: =IF(F30<>"",1+MAX($A$2:A29),"") -> 15 | D30: #350 THHN | E30: 4319.04 | F30: 0.05 | G30: =(F30*E30)+E30 -> 4534.992 | H30: LF | I30: 0.07 | J30: =+I30*G30 -> 317.44944 | K30: ='LABOR SHEET'!C$3 -> 128 | L30: =I30*K30 -> 8.96 | M30: =K30*J30 -> 40633.528 | N30: 13.24 | O30: =N30*G30 -> 60043.294 | P30: =(I30*K30)+N30 -> 22.2 | Q30: =P30*G30 -> 100676.82
A31: =IF(F31<>"",1+MAX($A$2:A30),"") -> 16 | D31: #4/0 THHN | E31: 451.56 | F31: 0.05 | G31: =(F31*E31)+E31 -> 474.138 | H31: LF | I31: 0.066 | J31: =+I31*G31 -> 31.293108 | K31: ='LABOR SHEET'!C$3 -> 128 | L31: =I31*K31 -> 8.448 | M31: =K31*J31 -> 4005.5178 | N31: 7.78 | O31: =N31*G31 -> 3688.7936 | P31: =(I31*K31)+N31 -> 16.228 | Q31: =P31*G31 -> 7694.3115
A32: =IF(F32<>"",1+MAX($A$2:A31),"") -> 17 | D32: #3/0 THHN | E32: 1079.76 | F32: 0.05 | G32: =(F32*E32)+E32 -> 1133.748 | H32: LF | I32: 0.06 | J32: =+I32*G32 -> 68.02488 | K32: ='LABOR SHEET'!C$3 -> 128 | L32: =I32*K32 -> 7.68 | M32: =K32*J32 -> 8707.1846 | N32: 6.33 | O32: =N32*G32 -> 7176.6248 | P32: =(I32*K32)+N32 -> 14.01 | Q32: =P32*G32 -> 15883.809
A33: =IF(F33<>"",1+MAX($A$2:A32),"") -> 18 | D33: #2 THHN | E33: 2523.72 | F33: 0.05 | G33: =(F33*E33)+E33 -> 2649.906 | H33: LF | I33: 0.025 | J33: =+I33*G33 -> 66.24765 | K33: ='LABOR SHEET'!C$3 -> 128 | L33: =I33*K33 -> 3.2 | M33: =K33*J33 -> 8479.6992 | N33: 2.97 | O33: =N33*G33 -> 7870.2208 | P33: =(I33*K33)+N33 -> 6.17 | Q33: =P33*G33 -> 16349.92
A34: =IF(F34<>"",1+MAX($A$2:A33),"") -> 19 | D34: #8 THHN | E34: 601.29 | F34: 0.05 | G34: =(F34*E34)+E34 -> 631.3545 | H34: LF | I34: 0.012 | J34: =+I34*G34 -> 7.576254 | K34: ='LABOR SHEET'!C$3 -> 128 | L34: =I34*K34 -> 1.536 | M34: =K34*J34 -> 969.76051 | N34: 0.82 | O34: =N34*G34 -> 517.71069 | P34: =(I34*K34)+N34 -> 2.356 | Q34: =P34*G34 -> 1487.4712
A35: =IF(F35<>"",1+MAX($A$2:A34),"")
A36: =IF(F36<>"",1+MAX($A$2:A35),"") | D36: GROUNDING
A37: =IF(F37<>"",1+MAX($A$2:A36),"") -> 20 | D37: #3/0 CU GROUND WIRE | E37: 40 | F37: 0 | G37: =(F37*E37)+E37 -> 40 | H37: LF | I37: 0.03 | J37: =+I37*G37 -> 1.2 | K37: ='LABOR SHEET'!C$3 -> 128 | L37: =I37*K37 -> 3.84 | M37: =K37*J37 -> 153.6 | N37: 5.54 | O37: =N37*G37 -> 221.6 | P37: =(I37*K37)+N37 -> 9.38 | Q37: =P37*G37 -> 375.2
A38: =IF(F38<>"",1+MAX($A$2:A37),"") -> 21 | D38: #6 CU GROUND WIRE | E38: 100 | F38: 0 | G38: =(F38*E38)+E38 -> 100 | H38: LF | I38: 0.015 | J38: =+I38*G38 -> 1.5 | K38: ='LABOR SHEET'!C$3 -> 128 | L38: =I38*K38 -> 1.92 | M38: =K38*J38 -> 192 | N38: 1.05 | O38: =N38*G38 -> 105 | P38: =(I38*K38)+N38 -> 2.97 | Q38: =P38*G38 -> 297
A39: =IF(F39<>"",1+MAX($A$2:A38),"") -> 22 | D39: 5/8"X10' GROUND ROD | E39: 10 | F39: 0.05 | G39: =(F39*E39)+E39 -> 10.5 | H39: EA | I39: 0.6 | J39: =+I39*G39 -> 6.3 | K39: ='LABOR SHEET'!C$3 -> 128 | L39: =I39*K39 -> 76.8 | M39: =K39*J39 -> 806.4 | N39: 49.99 | O39: =N39*G39 -> 524.895 | P39: =(I39*K39)+N39 -> 126.79 | Q39: =P39*G39 -> 1331.295
A40: =IF(F40<>"",1+MAX($A$2:A39),"") -> 23 | D40: EXOTHERMIC WELD | E40: 12 | F40: 0.05 | G40: =(F40*E40)+E40 -> 12.6 | H40: EA | I40: 0.25 | J40: =+I40*G40 -> 3.15 | K40: ='LABOR SHEET'!C$3 -> 128 | L40: =I40*K40 -> 32 | M40: =K40*J40 -> 403.2 | N40: 18 | O40: =N40*G40 -> 226.8 | P40: =(I40*K40)+N40 -> 50 | Q40: =P40*G40 -> 630
A41: =IF(F41<>"",1+MAX($A$2:A40),"") -> 24 | D41: GROUND BUS BAR | E41: 2 | F41: 0.05 | G41: =(F41*E41)+E41 -> 2.1 | H41: EA | I41: 1.22 | J41: =+I41*G41 -> 2.562 | K41: ='LABOR SHEET'!C$3 -> 128 | L41: =I41*K41 -> 156.16 | M41: =K41*J41 -> 327.936 | N41: 225 | O41: =N41*G41 -> 472.5 | P41: =(I41*K41)+N41 -> 381.16 | Q41: =P41*G41 -> 800.436
...

Sheet Add Alternate
A2: DETAILED BREAKDOWN OF ITEMS
B3: Project Name | D3: Joint Public Safety Facility
B4: Project Address | D4: 2100 w edgewood dr. port angeles, wa 98363
B5: Scope: | D5: Electrical
A6: S# | B6: Dwg. | C6: CSI NO | D6: DESCRIPTION | E6: QTY. | F6: Wastage | G6: Qty w/ Waste | H6: UNIT | I6: UNIT LABOR HOUR | J6: TOTAL LABOR HOUR | K6: LABOR WAGE/ HOUR | L6: UNIT LABOR COST | M6: TOTAL LABOR COST | N6: UNIT MATERIAL COST | O6: TOTAL MATERIAL COST | P6: UNIT PRICE (Labor & Material) | Q6: TRADE TOTAL
C7: 1 | D7: DIVISION 01-GENERAL REQUIREMENTS
A8: =IF(F8<>"",1+MAX($A$2:A7),"") -> 1 | D8: Permits | E8: 1 | F8: 0 | G8: =(F8*E8)+E8 -> 1 | H8: LS | I8: 0 | J8: =+I8*G8 -> 0 | K8: 0 | L8: =I8*K8 -> 0 | M8: =K8*J8 -> 0 | N8: 0 | O8: =N8*G8 -> 0 | P8: =(I8*K8)+N8 -> 0 | Q8: 1500
A9: =IF(F9<>"",1+MAX($A$2:A8),"") -> 2 | D9: Supervision and Coordination | E9: 1 | F9: 0 | G9: =(F9*E9)+E9 -> 1 | H9: LS | I9: 0 | J9: =+I9*G9 -> 0 | K9: 0 | L9: =I9*K9 -> 0 | M9: =K9*J9 -> 0 | N9: 0 | O9: =N9*G9 -> 0 | P9: =(I9*K9)+N9 -> 0
A10: =IF(F10<>"",1+MAX($A$2:A9),"") -> 3 | D10: Submittals and Shop drawings | E10: 1 | F10: 0 | G10: =(F10*E10)+E10 -> 1 | H10: LS | I10: 0 | J10: =+I10*G10 -> 0 | K10: 0 | L10: =I10*K10 -> 0 | M10: =K10*J10 -> 0 | N10: 0 | O10: =N10*G10 -> 0 | P10: =(I10*K10)+N10 -> 0
A11: =IF(F11<>"",1+MAX($A$2:A10),"") -> 4 | D11: Final Cleaning | E11: 1 | F11: 0 | G11: =(F11*E11)+E11 -> 1 | H11: LS | I11: 0 | J11: =+I11*G11 -> 0 | K11: 0 | L11: =I11*K11 -> 0 | M11: =K11*J11 -> 0 | N11: 0 | O11: =N11*G11 -> 0 | P11: =(I11*K11)+N11 -> 0
A12: =IF(F12<>"",1+MAX($A$2:A11),"") -> 5 | D12: Mobilization Costs | E12: 1 | F12: 0 | G12: =(F12*E12)+E12 -> 1 | H12: LS | I12: 0 | J12: =+I12*G12 -> 0 | K12: 0 | L12: =I12*K12 -> 0 | M12: =K12*J12 -> 0 | N12: 0 | O12: =N12*G12 -> 0 | P12: =(I12*K12)+N12 -> 0
A13: =IF(F13<>"",1+MAX($A$2:A12),"") -> 6 | D13: Temporary Control & Facilities | E13: 1 | F13: 0 | G13: =(F13*E13)+E13 -> 1 | H13: LS | I13: 0 | J13: =+I13*G13 -> 0 | K13: 0 | L13: =I13*K13 -> 0 | M13: =K13*J13 -> 0 | N13: 0 | O13: =N13*G13 -> 0 | P13: =(I13*K13)+N13 -> 0
A14: =IF(F14<>"",1+MAX($A$2:A13),"") -> 7 | D14: Scaffolding | E14: 1 | F14: 0 | G14: =(F14*E14)+E14 -> 1 | H14: LS | I14: 0 | J14: =+I14*G14 -> 0 | K14: 0 | L14: =I14*K14 -> 0 | M14: =K14*J14 -> 0 | N14: 0 | O14: =N14*G14 -> 0 | P14: =(I14*K14)+N14 -> 0
A15: =IF(F15<>"",1+MAX($A$2:A14),"") | D15: SUBTOTAL | Q15: =SUM(Q8:Q14) -> 1500
A16: =IF(F16<>"",1+MAX($A$2:A15),"")
A17: =IF(F17<>"",1+MAX($A$2:A16),"") | D17: ADD ALTERNATE (PEDESTRIAN GATE CARD READER)
A18: =IF(F18<>"",1+MAX($A$2:A17),"") | D18: EQUIPMENT CONNECTION
A19: =IF(F19<>"",1+MAX($A$2:A18),"") -> 8 | D19: CONNECTION FOR PEDESTRIAN GATE CARD READER | E19: 2 | F19: 0 | G19: =(F19*E19)+E19 -> 2 | H19: EA | I19: 0.25 | J19: =+I19*G19 -> 0.5 | K19: ='LABOR SHEET'!C$3 -> 128 | L19: =I19*K19 -> 32 | M19: =K19*J19 -> 64 | N19: 18 | O19: =N19*G19 -> 36 | P19: =(I19*K19)+N19 -> 50 | Q19: =P19*G19 -> 100
A20: =IF(F20<>"",1+MAX($A$2:A19),"")
A21: =IF(F21<>"",1+MAX($A$2:A20),"") | D21: MISCELLANEOUS
A22: =IF(F22<>"",1+MAX($A$2:A21),"") -> 9 | D22: TRENCHING AND BACKFILLING | E22: 89.02 | F22: 0 | G22: =(F22*E22)+E22 -> 89.02 | H22: LF | I22: 0.045 | J22: =+I22*G22 -> 4.0059 | K22: ='LABOR SHEET'!C$3 -> 128 | L22: =I22*K22 -> 5.76 | M22: =K22*J22 -> 512.7552 | N22: 1.2 | O22: =N22*G22 -> 106.824 | P22: =(I22*K22)+N22 -> 6.96 | Q22: =P22*G22 -> 619.5792
A23: =IF(F23<>"",1+MAX($A$2:A22),"")
A24: =IF(F24<>"",1+MAX($A$2:A23),"") | D24: POWER CIRCUITS
A25: =IF(F25<>"",1+MAX($A$2:A24),"") | D25: CONDUITS
A26: =IF(F26<>"",1+MAX($A$2:A25),"") -> 10 | D26: 1"C PVC | E26: 390.21 | F26: 0.05 | G26: =(F26*E26)+E26 -> 409.7205 | H26: LF | I26: 0.05 | J26: =+I26*G26 -> 20.486025 | K26: ='LABOR SHEET'!C$3 -> 128 | L26: =I26*K26 -> 6.4 | M26: =K26*J26 -> 2622.2112 | N26: =11.46/10+0.25 -> 1.396 | O26: =N26*G26 -> 571.96982 | P26: =(I26*K26)+N26 -> 7.796 | Q26: =P26*G26 -> 3194.181
A27: =IF(F27<>"",1+MAX($A$2:A26),"") -> 11 | D27: 3/4"C EMT | E27: 5 | F27: 0.05 | G27: =(F27*E27)+E27 -> 5.25 | H27: LF | I27: 0.035 | J27: =+I27*G27 -> 0.18375 | K27: ='LABOR SHEET'!C$3 -> 128 | L27: =I27*K27 -> 4.48 | M27: =K27*J27 -> 23.52 | N27: =9.68/10+0.35 -> 1.318 | O27: =N27*G27 -> 6.9195 | P27: =(I27*K27)+N27 -> 5.798 | Q27: =P27*G27 -> 30.4395
A28: =IF(F28<>"",1+MAX($A$2:A27),"") -> 12 | D28: 3/4"C LFMC | E28: 12.85 | F28: 0.05 | G28: =(F28*E28)+E28 -> 13.4925 | H28: LF | I28: 0.1 | J28: =+I28*G28 -> 1.34925 | K28: ='LABOR SHEET'!C$3 -> 128 | L28: =I28*K28 -> 12.8 | M28: =K28*J28 -> 172.704 | N28: =244.56/100+0.3 -> 2.7456 | O28: =N28*G28 -> 37.045008 | P28: =(I28*K28)+N28 -> 15.5456 | Q28: =P28*G28 -> 209.74901
A29: =IF(F29<>"",1+MAX($A$2:A28),"") -> 13 | D29: 3/4"C RGS | E29: 10.27 | F29: 0.05 | G29: =(F29*E29)+E29 -> 10.7835 | H29: LF | I29: 0.067 | J29: =+I29*G29 -> 0.7224945 | K29: ='LABOR SHEET'!C$3 -> 128 | L29: =I29*K29 -> 8.576 | M29: =K29*J29 -> 92.479296 | N29: =29.67/10+0.35 -> 3.317 | O29: =N29*G29 -> 35.76887 | P29: =(I29*K29)+N29 -> 11.893 | Q29: =P29*G29 -> 128.24817
A30: =IF(F30<>"",1+MAX($A$2:A29),"")
A31: =IF(F31<>"",1+MAX($A$2:A30),"") | D31: CONDUTORS
A32: =IF(F32<>"",1+MAX($A$2:A31),"") -> 14 | D32: #10 THHN SOLID | E32: 1254.99 | F32: 0.05 | G32: =(F32*E32)+E32 -> 1317.7395 | H32: LF | I32: 0.01 | J32: =+I32*G32 -> 13.177395 | K32: ='LABOR SHEET'!C$3 -> 128 | L32: =I32*K32 -> 1.28 | M32: =K32*J32 -> 1686.7066 | N32: 0.38 | O32: =N32*G32 -> 500.74101 | P32: =(I32*K32)+N32 -> 1.66 | Q32: =P32*G32 -> 2187.4476
A33: =IF(F33<>"",1+MAX($A$2:A32),"")
A34: =IF(F34<>"",1+MAX($A$2:A33),"") | D34: SECURITY
A35: =IF(F35<>"",1+MAX($A$2:A34),"") | D35: CONDIUTS
A36: =IF(F36<>"",1+MAX($A$2:A35),"") -> 15 | D36: 1"C PVC | E36: 110.05 | F36: 0.05 | G36: =(F36*E36)+E36 -> 115.5525 | H36: LF | I36: 0.05 | J36: =+I36*G36 -> 5.777625 | K36: ='LABOR SHEET'!C$3 -> 128 | L36: =I36*K36 -> 6.4 | M36: =K36*J36 -> 739.536 | N36: =11.46/10+0.25 -> 1.396 | O36: =N36*G36 -> 161.31129 | P36: =(I36*K36)+N36 -> 7.796 | Q36: =P36*G36 -> 900.84729
A37: =IF(F37<>"",1+MAX($A$2:A36),"") -> 16 | D37: 3/4"C RGS | E37: 14.52 | F37: 0.05 | G37: =(F37*E37)+E37 -> 15.246 | H37: LF | I37: 0.067 | J37: =+I37*G37 -> 1.021482 | K37: ='LABOR SHEET'!C$3 -> 128 | L37: =I37*K37 -> 8.576 | M37: =K37*J37 -> 130.7497 | N37: =29.67/10+0.35 -> 3.317 | O37: =N37*G37 -> 50.570982 | P37: =(I37*K37)+N37 -> 11.893 | Q37: =P37*G37 -> 181.32068
A38: =IF(F38<>"",1+MAX($A$2:A37),"")
A39: =IF(F39<>"",1+MAX($A$2:A38),"") | D39: CONDUCTORS
A40: =IF(F40<>"",1+MAX($A$2:A39),"") -> 17 | D40: CAT 6 | E40: 124.57 | F40: 0.05 | G40: =(F40*E40)+E40 -> 130.7985 | H40: LF | I40: 0.008 | J40: =+I40*G40 -> 1.046388 | K40: ='LABOR SHEET'!C$3 -> 128 | L40: =I40*K40 -> 1.024 | M40: =K40*J40 -> 133.93766 | N40: =7.94/15 -> 0.52933333 | O40: =N40*G40 -> 69.236006 | P40: =(I40*K40)+N40 -> 1.5533333 | Q40: =P40*G40 -> 203.17367
A41: =IF(F41<>"",1+MAX($A$2:A40),"")
...

Sheet LABOR SHEET
B1: Labor Type | C1: Labor Rate
A3: Electrical | B3: Elec | C3: 128
B7: Wastage
A8: Each/Count | B8: EA | C8: 0
A9: Linear Footage | B9: LF | C9: 0.05
A10: Square Footage | B10: SF | C10: 0.1
A11: Square Yard | B11: SY | C11: 0.1
A12: Cubic Yard | B12: CY | C12: 0.1
A13: Lumpsum | B13: LS | C13: 0
A14: Survery | B14: Survey | C14: 0
A15: Stair Riser | B15: RISER | C15: 0
A16: Blocks Count | B16: BLOCKS | C16: 0
A17: Bags of Pre-Mix Mortar | B17: BAGS | C17: 0
A18: Linear Footage of Wall | B18: LF.Wall | C18: 0.1
A19: Pounds | B19: LBS | C19: 0.1
... A30: N/A | B30: N/A | C30: 0
A33: NOTE:
A34: Prevailing wages have been included in this estimate in compliance with the Davis-Bacon Act.
A35: Material pricing is based on current market rates sourced from reputable online platforms and suppliers.
A36: Please note that actual costs may vary depending on site-specific conditions, unforeseen circumstances, or changes in market conditions.
