Workbook

Sheet General Summary
A1: GENERAL SUMMARY
A2: DIVISION NO. | B2: DESCRIPTION | C2: TOTAL DIV. COST
A3: 1000 | B3: General Requirments | C3: ='Base Bid'!R13 -> 54000
A4: 22000 | B4: Plumbing | C4: ='Base Bid'!R362 -> 539602.91
B5: TOTAL COST | C5: =SUM(C3:C4) -> 593602.91
A7: TOTAL COST | D7: =C5 -> 593602.91
A8: CONTIGENCIES | C8: 0.05 | D8: =D7*C8 -> 29680.146
A9: OVERHEAD AND PROFIT | C9: 0.1 | D9: =D7*C9 -> 59360.291
A10: TAX | C10: 0.105 | D10: =D7*C10 -> 62328.306
A11: PERFORMANCE AND PAYMENT BONDS | C11: 0.015 | D11: =D7*C11 -> 8904.0437
A12: TOTAL BASEBID | C12: =SUM(D7:D11) -> 753875.7
A15: GENERAL SUMMARY
A16: DIVISION NO. | B16: DESCRIPTION | C16: TOTAL DIV. COST
A17: 1000 | B17: General Requirments | C17: =Alternate!R13 -> 54000
A18: 22000 | B18: Plumbing | C18: =Alternate!R362 -> 470944.52
B19: TOTAL COST | C19: =SUM(C17:C18) -> 524944.52
A21: TOTAL COST | D21: =C19 -> 524944.52
A22: CONTIGENCIES | C22: 0.05 | D22: =D21*C22 -> 26247.226
A23: OVERHEAD AND PROFIT | C23: 0.1 | D23: =D21*C23 -> 52494.452
A24: TAX | C24: 0.105 | D24: =D21*C24 -> 55119.175
A25: PERFORMANCE AND PAYMENT BONDS | C25: 0.015 | D25: =D21*C25 -> 7874.1678
A26: TOTAL ALTERNATE BID | C26: =SUM(D21:D25) -> 666679.54

Sheet Base Bid
A1: DETAILED BREAKDOWN OF ITEMS
A2: Project Name: CHUZE FITNESS LONG BEACH CA | I2: Address: 2185E. SOUTH STREET LONG BEACH, CA 90805
A3: S# | B3: Dwg. | C3: CSI NO | D3: DESCRIPTION | E3: QTY. | F3: UNIT | G3: WASTAGE | H3: QTY. W/ WASTAGE | I3: UNIT MATERIAL COST | J3: TOTAL MATERIAL COST | K3: UNIT LABOR HOUR | L3: TOTAL LABOR HOUR | M3: LABOR WAGE/ HOUR | N3: UNIT LABOR COST | O3: TOTAL LABOR COST | P3: UNIT COST (Labor + Material) | Q3: TOTAL COST | R3: TRADE TOTAL
C4: 1 | D4: DIVISION 01-GENERAL REQUIREMENTS
A5: =IF(G5<>"",1+MAX($A$3:A4),"") -> 1 | D5: Permits | E5: 1 | F5: LS | G5: 0 | H5: =(G5*E5)+E5 -> 1 | I5: 0 | J5: =I5*H5 -> 0 | K5: 0 | L5: =+K5*H5 -> 0 | M5: 0 | N5: =K5*M5 -> 0 | O5: =M5*L5 -> 0 | P5: =I5+N5 -> 0 | Q5: 54000
A6: =IF(G6<>"",1+MAX($A$3:A5),"") -> 2 | D6: Supervision and Coordination | E6: 1 | F6: LS | G6: 0 | H6: =(G6*E6)+E6 -> 1 | I6: 0 | J6: =I6*H6 -> 0 | K6: 0 | L6: =+K6*H6 -> 0 | M6: 0 | N6: =K6*M6 -> 0 | O6: =M6*L6 -> 0 | P6: =I6+N6 -> 0
A7: =IF(G7<>"",1+MAX($A$3:A6),"") -> 3 | D7: Submittals and Shop drawings | E7: 1 | F7: LS | G7: 0 | H7: =(G7*E7)+E7 -> 1 | I7: 0 | J7: =I7*H7 -> 0 | K7: 0 | L7: =+K7*H7 -> 0 | M7: 0 | N7: =K7*M7 -> 0 | O7: =M7*L7 -> 0 | P7: =I7+N7 -> 0
A8: =IF(G8<>"",1+MAX($A$3:A7),"") -> 4 | D8: Final Cleaning | E8: 1 | F8: LS | G8: 0 | H8: =(G8*E8)+E8 -> 1 | I8: 0 | J8: =I8*H8 -> 0 | K8: 0 | L8: =+K8*H8 -> 0 | M8: 0 | N8: =K8*M8 -> 0 | O8: =M8*L8 -> 0 | P8: =I8+N8 -> 0
A9: =IF(G9<>"",1+MAX($A$3:A8),"") -> 5 | D9: Mobilization Costs | E9: 1 | F9: LS | G9: 0 | H9: =(G9*E9)+E9 -> 1 | I9: 0 | J9: =I9*H9 -> 0 | K9: 0 | L9: =+K9*H9 -> 0 | M9: 0 | N9: =K9*M9 -> 0 | O9: =M9*L9 -> 0 | P9: =I9+N9 -> 0
A10: =IF(G10<>"",1+MAX($A$3:A9),"") -> 6 | D10: Temporary Control & Facilities | E10: 1 | F10: LS | G10: 0 | H10: =(G10*E10)+E10 -> 1 | I10: 0 | J10: =I10*H10 -> 0 | K10: 0 | L10: =+K10*H10 -> 0 | M10: 0 | N10: =K10*M10 -> 0 | O10: =M10*L10 -> 0 | P10: =I10+N10 -> 0
A11: =IF(G11<>"",1+MAX($A$3:A10),"") -> 7 | D11: Scaffolding | E11: 1 | F11: LS | G11: 0 | H11: =(G11*E11)+E11 -> 1 | I11: 0 | J11: =I11*H11 -> 0 | K11: 0 | L11: =+K11*H11 -> 0 | M11: 0 | N11: =K11*M11 -> 0 | O11: =M11*L11 -> 0 | P11: =I11+N11 -> 0
A12: =IF(G12<>"",1+MAX($A$3:A11),"")
A13: =IF(G13<>"",1+MAX($A$3:A12),"") | D13: SUBTOTAL | R13: =SUM(Q4:Q13) -> 54000
A14: =IF(G14<>"",1+MAX($A$3:A13),"")
A15: =IF(G15<>"",1+MAX($A$3:A14),"") | C15: 22 | D15: DIVISION 22- PLUMBING
A16: =IF(G16<>"",1+MAX($A$3:A15),"") | D16: GAS PIPES
A17: =IF(G17<>"",1+MAX($A$3:A16),"") | D17: SCHEDULE 40 BLACK STEEL PIPE ASTM A53, W/ FITTINGS ASME B16.3 W/ WEATHER PROOF COAT
A18: =IF(G18<>"",1+MAX($A$3:A17),"") -> 8 | D18: 3/4" Dia Gas Pipe | E18: 64.85 | F18: LF | G18: 0.05 | H18: =E18*(1+G18) -> 68.0925 | I18: =4/1*0.75 -> 3 | J18: =I18*H18 -> 204.2775 | K18: 0.105 | L18: =+K18*H18 -> 7.1497125 | M18: ='LABOR SHEET'!C$5 -> 57.65 | N18: =K18*M18 -> 6.05325 | O18: =M18*L18 -> 412.18093 | P18: =I18+N18 -> 9.05325 | Q18: =P18*H18 -> 616.45843
A19: =IF(G19<>"",1+MAX($A$3:A18),"") -> 9 | D19: 1" Dia Gas Pipe | E19: 145.27 | F19: LF | G19: 0.05 | H19: =E19*(1+G19) -> 152.5335 | I19: =5.02/1.25 -> 4.016 | J19: =I19*H19 -> 612.57454 | K19: 0.125 | L19: =+K19*H19 -> 19.066688 | M19: ='LABOR SHEET'!C$5 -> 57.65 | N19: =K19*M19 -> 7.20625 | O19: =M19*L19 -> 1099.1945 | P19: =I19+N19 -> 11.22225 | Q19: =P19*H19 -> 1711.7691
A20: =IF(G20<>"",1+MAX($A$3:A19),"") -> 10 | D20: 1-1/4" Dia Gas Pipe | E20: 341.28 | F20: LF | G20: 0.05 | H20: =E20*(1+G20) -> 358.344 | I20: 5.02 | J20: =I20*H20 -> 1798.8869 | K20: 0.18 | L20: =+K20*H20 -> 64.50192 | M20: ='LABOR SHEET'!C$5 -> 57.65 | N20: =K20*M20 -> 10.377 | O20: =M20*L20 -> 3718.5357 | P20: =I20+N20 -> 15.397 | Q20: =P20*H20 -> 5517.4226
A21: =IF(G21<>"",1+MAX($A$3:A20),"") -> 11 | D21: 1-1/2" Dia Gas Pipe | E21: 29.58 | F21: LF | G21: 0.05 | H21: =E21*(1+G21) -> 31.059 | I21: 5.86 | J21: =I21*H21 -> 182.00574 | K21: 0.2 | L21: =+K21*H21 -> 6.2118 | M21: ='LABOR SHEET'!C$5 -> 57.65 | N21: =K21*M21 -> 11.53 | O21: =M21*L21 -> 358.11027 | P21: =I21+N21 -> 17.39 | Q21: =P21*H21 -> 540.11601
A22: =IF(G22<>"",1+MAX($A$3:A21),"") -> 12 | D22: 2" Dia Gas Pipe | E22: 224.28 | F22: LF | G22: 0.05 | H22: =E22*(1+G22) -> 235.494 | I22: 7.25 | J22: =I22*H22 -> 1707.3315 | K22: 0.262 | L22: =+K22*H22 -> 61.699428 | M22: ='LABOR SHEET'!C$5 -> 57.65 | N22: =K22*M22 -> 15.1043 | O22: =M22*L22 -> 3556.972 | P22: =I22+N22 -> 22.3543 | Q22: =P22*H22 -> 5264.3035
A23: =IF(G23<>"",1+MAX($A$3:A22),"") -> 13 | D23: 2-1/2" Dia Gas Pipe | E23: 111.67 | F23: LF | G23: 0.05 | H23: =E23*(1+G23) -> 117.2535 | I23: 15.11 | J23: =I23*H23 -> 1771.7004 | K23: 0.32 | L23: =+K23*H23 -> 37.52112 | M23: ='LABOR SHEET'!C$5 -> 57.65 | N23: =K23*M23 -> 18.448 | O23: =M23*L23 -> 2163.0926 | P23: =I23+N23 -> 33.558 | Q23: =P23*H23 -> 3934.793
A24: =IF(G24<>"",1+MAX($A$3:A23),"") -> 14 | D24: 3" Dia Gas Pipe | E24: 193.04 | F24: LF | G24: 0.05 | H24: =E24*(1+G24) -> 202.692 | I24: =28.82/4*3 -> 21.615 | J24: =I24*H24 -> 4381.1876 | K24: 0.365 | L24: =+K24*H24 -> 73.98258 | M24: ='LABOR SHEET'!C$5 -> 57.65 | N24: =K24*M24 -> 21.04225 | O24: =M24*L24 -> 4265.0957 | P24: =I24+N24 -> 42.65725 | Q24: =P24*H24 -> 8646.2833
A25: =IF(G25<>"",1+MAX($A$3:A24),"") -> 15 | D25: 4" Dia Gas Pipe | E25: 66.58 | F25: LF | G25: 0.05 | H25: =E25*(1+G25) -> 69.909 | I25: 28.82 | J25: =I25*H25 -> 2014.7774 | K25: 0.444 | L25: =+K25*H25 -> 31.039596 | M25: ='LABOR SHEET'!C$5 -> 57.65 | N25: =K25*M25 -> 25.5966 | O25: =M25*L25 -> 1789.4327 | P25: =I25+N25 -> 54.4166 | Q25: =P25*H25 -> 3804.2101
A26: =IF(G26<>"",1+MAX($A$3:A25),"")
A27: =IF(G27<>"",1+MAX($A$3:A26),"") | D27: FITTINGS
A28: =IF(G28<>"",1+MAX($A$3:A27),"") -> 16 | D28: 3/4" Dia Gas Pipe 90 Deg Elbow | E28: 5 | F28: EA | G28: 0 | H28: =E28*(1+G28) -> 5 | I28: 4.59 | J28: =I28*H28 -> 22.95 | K28: 0.55 | L28: =+K28*H28 -> 2.75 | M28: ='LABOR SHEET'!C$5 -> 57.65 | N28: =K28*M28 -> 31.7075 | O28: =M28*L28 -> 158.5375 | P28: =I28+N28 -> 36.2975 | Q28: =P28*H28 -> 181.4875
A29: =IF(G29<>"",1+MAX($A$3:A28),"") -> 17 | D29: 1" Dia Gas Pipe 90 Deg Elbow | E29: 12 | F29: EA | G29: 0 | H29: =E29*(1+G29) -> 12 | I29: 8.5 | J29: =I29*H29 -> 102 | K29: 0.56 | L29: =+K29*H29 -> 6.72 | M29: ='LABOR SHEET'!C$5 -> 57.65 | N29: =K29*M29 -> 32.284 | O29: =M29*L29 -> 387.408 | P29: =I29+N29 -> 40.784 | Q29: =P29*H29 -> 489.408
A30: =IF(G30<>"",1+MAX($A$3:A29),"") -> 18 | D30: 1-1/4" Dia Gas Pipe 90 Deg Elbow | E30: 25 | F30: EA | G30: 0 | H30: =E30*(1+G30) -> 25 | I30: 9.1 | J30: =I30*H30 -> 227.5 | K30: 0.57 | L30: =+K30*H30 -> 14.25 | M30: ='LABOR SHEET'!C$5 -> 57.65 | N30: =K30*M30 -> 32.8605 | O30: =M30*L30 -> 821.5125 | P30: =I30+N30 -> 41.9605 | Q30: =P30*H30 -> 1049.0125
A31: =IF(G31<>"",1+MAX($A$3:A30),"") -> 19 | D31: 1-1/2" Dia Gas Pipe 90 Deg Elbow | E31: 1 | F31: EA | G31: 0 | H31: =E31*(1+G31) -> 1 | I31: 12.1 | J31: =I31*H31 -> 12.1 | K31: 0.58 | L31: =+K31*H31 -> 0.58 | M31: ='LABOR SHEET'!C$5 -> 57.65 | N31: =K31*M31 -> 33.437 | O31: =M31*L31 -> 33.437 | P31: =I31+N31 -> 45.537 | Q31: =P31*H31 -> 45.537
A32: =IF(G32<>"",1+MAX($A$3:A31),"") -> 20 | D32: 2" Dia Gas Pipe 90 Deg Elbow | E32: 5 | F32: EA | G32: 0 | H32: =E32*(1+G32) -> 5 | I32: 15.2 | J32: =I32*H32 -> 76 | K32: 0.59 | L32: =+K32*H32 -> 2.95 | M32: ='LABOR SHEET'!C$5 -> 57.65 | N32: =K32*M32 -> 34.0135 | O32: =M32*L32 -> 170.0675 | P32: =I32+N32 -> 49.2135 | Q32: =P32*H32 -> 246.0675
A33: =IF(G33<>"",1+MAX($A$3:A32),"") -> 21 | D33: 2-1/2" Dia Gas Pipe 90 Deg Elbow | E33: 4 | F33: EA | G33: 0 | H33: =E33*(1+G33) -> 4 | I33: 22.5 | J33: =I33*H33 -> 90 | K33: 0.6 | L33: =+K33*H33 -> 2.4 | M33: ='LABOR SHEET'!C$5 -> 57.65 | N33: =K33*M33 -> 34.59 | O33: =M33*L33 -> 138.36 | P33: =I33+N33 -> 57.09 | Q33: =P33*H33 -> 228.36
A34: =IF(G34<>"",1+MAX($A$3:A33),"") -> 22 | D34: 3" Dia Gas Pipe 90 Deg Elbow | E34: 2 | F34: EA | G34: 0 | H34: =E34*(1+G34) -> 2 | I34: 32.53 | J34: =I34*H34 -> 65.06 | K34: 0.61 | L34: =+K34*H34 -> 1.22 | M34: ='LABOR SHEET'!C$5 -> 57.65 | N34: =K34*M34 -> 35.1665 | O34: =M34*L34 -> 70.333 | P34: =I34+N34 -> 67.6965 | Q34: =P34*H34 -> 135.393
A35: =IF(G35<>"",1+MAX($A$3:A34),"") -> 23 | D35: 3/4" Dia Gas Pipe Tee | E35: 2 | F35: EA | G35: 0 | H35: =E35*(1+G35) -> 2 | I35: 6.45 | J35: =I35*H35 -> 12.9 | K35: 0.65 | L35: =+K35*H35 -> 1.3 | M35: ='LABOR SHEET'!C$5 -> 57.65 | N35: =K35*M35 -> 37.4725 | O35: =M35*L35 -> 74.945 | P35: =I35+N35 -> 43.9225 | Q35: =P35*H35 -> 87.845
A36: =IF(G36<>"",1+MAX($A$3:A35),"") -> 24 | D36: 1" Dia Gas Pipe Tee | E36: 4 | F36: EA | G36: 0 | H36: =E36*(1+G36) -> 4 | I36: 12.5 | J36: =I36*H36 -> 50 | K36: 0.67 | L36: =+K36*H36 -> 2.68 | M36: ='LABOR SHEET'!C$5 -> 57.65 | N36: =K36*M36 -> 38.6255 | O36: =M36*L36 -> 154.502 | P36: =I36+N36 -> 51.1255 | Q36: =P36*H36 -> 204.502
A37: =IF(G37<>"",1+MAX($A$3:A36),"") -> 25 | D37: 1-1/4" / 1" Dia Gas Pipe Tee | E37: 1 | F37: EA | G37: 0 | H37: =E37*(1+G37) -> 1 | I37: 18.25 | J37: =I37*H37 -> 18.25 | K37: 0.68 | L37: =+K37*H37 -> 0.68 | M37: ='LABOR SHEET'!C$5 -> 57.65 | N37: =K37*M37 -> 39.202 | O37: =M37*L37 -> 39.202 | P37: =I37+N37 -> 57.452 | Q37: =P37*H37 -> 57.452
A38: =IF(G38<>"",1+MAX($A$3:A37),"") -> 26 | D38: 1-1/4" Dia Gas Pipe Tee | E38: 7 | F38: EA | G38: 0 | H38: =E38*(1+G38) -> 7 | I38: 25.5 | J38: =I38*H38 -> 178.5 | K38: 0.69 | L38: =+K38*H38 -> 4.83 | M38: ='LABOR SHEET'!C$5 -> 57.65 | N38: =K38*M38 -> 39.7785 | O38: =M38*L38 -> 278.4495 | P38: =I38+N38 -> 65.2785 | Q38: =P38*H38 -> 456.9495
A39: =IF(G39<>"",1+MAX($A$3:A38),"") -> 27 | D39: 2" / 3/4" Dia Gas Pipe Tee | E39: 2 | F39: EA | G39: 0 | H39: =E39*(1+G39) -> 2 | I39: 30.5 | J39: =I39*H39 -> 61 | K39: 0.7 | L39: =+K39*H39 -> 1.4 | M39: ='LABOR SHEET'!C$5 -> 57.65 | N39: =K39*M39 -> 40.355 | O39: =M39*L39 -> 80.71 | P39: =I39+N39 -> 70.855 | Q39: =P39*H39 -> 141.71
... A56: =IF(G56<>"",1+MAX($A$3:A55),"") -> 44 | D56: 4" / 3" Dia Gas Pipe Reducer | E56: 1 | F56: EA | G56: 0 | H56: =E56*(1+G56) -> 1 | I56: 70.34 | J56: =I56*H56 -> 70.34 | K56: 0.53 | L56: =+K56*H56 -> 0.53 | M56: ='LABOR SHEET'!C$5 -> 57.65 | N56: =K56*M56 -> 30.5545 | O56: =M56*L56 -> 30.5545 | P56: =I56+N56 -> 100.8945 | Q56: =P56*H56 -> 100.8945
...

Sheet Alternate
A1: DETAILED BREAKDOWN OF ITEMS
A2: Project Name: CHUZE FITNESS LONG BEACH CA | I2: Address: 2185E. SOUTH STREET LONG BEACH, CA 90805
A3: S# | B3: Dwg. | C3: CSI NO | D3: DESCRIPTION | E3: QTY. | F3: UNIT | G3: WASTAGE | H3: QTY. W/ WASTAGE | I3: UNIT MATERIAL COST | J3: TOTAL MATERIAL COST | K3: UNIT LABOR HOUR | L3: TOTAL LABOR HOUR | M3: LABOR WAGE/ HOUR | N3: UNIT LABOR COST | O3: TOTAL LABOR COST | P3: UNIT COST (Labor + Material) | Q3: TOTAL COST | R3: TRADE TOTAL
C4: 1 | D4: DIVISION 01-GENERAL REQUIREMENTS
A5: =IF(G5<>"",1+MAX($A$3:A4),"") -> 1 | D5: Permits | E5: 1 | F5: LS | G5: 0 | H5: =(G5*E5)+E5 -> 1 | I5: 0 | J5: =I5*H5 -> 0 | K5: 0 | L5: =+K5*H5 -> 0 | M5: 0 | N5: =K5*M5 -> 0 | O5: =M5*L5 -> 0 | P5: =I5+N5 -> 0 | Q5: 54000
A6: =IF(G6<>"",1+MAX($A$3:A5),"") -> 2 | D6: Supervision and Coordination | E6: 1 | F6: LS | G6: 0 | H6: =(G6*E6)+E6 -> 1 | I6: 0 | J6: =I6*H6 -> 0 | K6: 0 | L6: =+K6*H6 -> 0 | M6: 0 | N6: =K6*M6 -> 0 | O6: =M6*L6 -> 0 | P6: =I6+N6 -> 0
A7: =IF(G7<>"",1+MAX($A$3:A6),"") -> 3 | D7: Submittals and Shop drawings | E7: 1 | F7: LS | G7: 0 | H7: =(G7*E7)+E7 -> 1 | I7: 0 | J7: =I7*H7 -> 0 | K7: 0 | L7: =+K7*H7 -> 0 | M7: 0 | N7: =K7*M7 -> 0 | O7: =M7*L7 -> 0 | P7: =I7+N7 -> 0
A8: =IF(G8<>"",1+MAX($A$3:A7),"") -> 4 | D8: Final Cleaning | E8: 1 | F8: LS | G8: 0 | H8: =(G8*E8)+E8 -> 1 | I8: 0 | J8: =I8*H8 -> 0 | K8: 0 | L8: =+K8*H8 -> 0 | M8: 0 | N8: =K8*M8 -> 0 | O8: =M8*L8 -> 0 | P8: =I8+N8 -> 0
A9: =IF(G9<>"",1+MAX($A$3:A8),"") -> 5 | D9: Mobilization Costs | E9: 1 | F9: LS | G9: 0 | H9: =(G9*E9)+E9 -> 1 | I9: 0 | J9: =I9*H9 -> 0 | K9: 0 | L9: =+K9*H9 -> 0 | M9: 0 | N9: =K9*M9 -> 0 | O9: =M9*L9 -> 0 | P9: =I9+N9 -> 0
A10: =IF(G10<>"",1+MAX($A$3:A9),"") -> 6 | D10: Temporary Control & Facilities | E10: 1 | F10: LS | G10: 0 | H10: =(G10*E10)+E10 -> 1 | I10: 0 | J10: =I10*H10 -> 0 | K10: 0 | L10: =+K10*H10 -> 0 | M10: 0 | N10: =K10*M10 -> 0 | O10: =M10*L10 -> 0 | P10: =I10+N10 -> 0
A11: =IF(G11<>"",1+MAX($A$3:A10),"") -> 7 | D11: Scaffolding | E11: 1 | F11: LS | G11: 0 | H11: =(G11*E11)+E11 -> 1 | I11: 0 | J11: =I11*H11 -> 0 | K11: 0 | L11: =+K11*H11 -> 0 | M11: 0 | N11: =K11*M11 -> 0 | O11: =M11*L11 -> 0 | P11: =I11+N11 -> 0
A12: =IF(G12<>"",1+MAX($A$3:A11),"")
A13: =IF(G13<>"",1+MAX($A$3:A12),"") | D13: SUBTOTAL | R13: =SUM(Q4:Q13) -> 54000
A14: =IF(G14<>"",1+MAX($A$3:A13),"")
A15: =IF(G15<>"",1+MAX($A$3:A14),"") | C15: 22 | D15: DIVISION 22- PLUMBING
A16: =IF(G16<>"",1+MAX($A$3:A15),"") | D16: GAS PIPES
A17: =IF(G17<>"",1+MAX($A$3:A16),"") | D17: SCHEDULE 40 BLACK STEEL PIPE ASTM A53, W/ FITTINGS ASME B16.3 W/ WEATHER PROOF COAT
A18: =IF(G18<>"",1+MAX($A$3:A17),"") -> 8 | D18: 3/4" Dia Gas Pipe | E18: 64.85 | F18: LF | G18: 0.05 | H18: =E18*(1+G18) -> 68.0925 | I18: =4/1*0.75 -> 3 | J18: =I18*H18 -> 204.2775 | K18: 0.105 | L18: =+K18*H18 -> 7.1497125 | M18: ='LABOR SHEET'!C$5 -> 57.65 | N18: =K18*M18 -> 6.05325 | O18: =M18*L18 -> 412.18093 | P18: =I18+N18 -> 9.05325 | Q18: =P18*H18 -> 616.45843
A19: =IF(G19<>"",1+MAX($A$3:A18),"") -> 9 | D19: 1" Dia Gas Pipe | E19: 145.27 | F19: LF | G19: 0.05 | H19: =E19*(1+G19) -> 152.5335 | I19: =5.02/1.25 -> 4.016 | J19: =I19*H19 -> 612.57454 | K19: 0.125 | L19: =+K19*H19 -> 19.066688 | M19: ='LABOR SHEET'!C$5 -> 57.65 | N19: =K19*M19 -> 7.20625 | O19: =M19*L19 -> 1099.1945 | P19: =I19+N19 -> 11.22225 | Q19: =P19*H19 -> 1711.7691
A20: =IF(G20<>"",1+MAX($A$3:A19),"") -> 10 | D20: 1-1/4" Dia Gas Pipe | E20: 341.28 | F20: LF | G20: 0.05 | H20: =E20*(1+G20) -> 358.344 | I20: 5.02 | J20: =I20*H20 -> 1798.8869 | K20: 0.18 | L20: =+K20*H20 -> 64.50192 | M20: ='LABOR SHEET'!C$5 -> 57.65 | N20: =K20*M20 -> 10.377 | O20: =M20*L20 -> 3718.5357 | P20: =I20+N20 -> 15.397 | Q20: =P20*H20 -> 5517.4226
A21: =IF(G21<>"",1+MAX($A$3:A20),"") -> 11 | D21: 1-1/2" Dia Gas Pipe | E21: 29.58 | F21: LF | G21: 0.05 | H21: =E21*(1+G21) -> 31.059 | I21: 5.86 | J21: =I21*H21 -> 182.00574 | K21: 0.2 | L21: =+K21*H21 -> 6.2118 | M21: ='LABOR SHEET'!C$5 -> 57.65 | N21: =K21*M21 -> 11.53 | O21: =M21*L21 -> 358.11027 | P21: =I21+N21 -> 17.39 | Q21: =P21*H21 -> 540.11601
A22: =IF(G22<>"",1+MAX($A$3:A21),"") -> 12 | D22: 2" Dia Gas Pipe | E22: 224.28 | F22: LF | G22: 0.05 | H22: =E22*(1+G22) -> 235.494 | I22: 7.25 | J22: =I22*H22 -> 1707.3315 | K22: 0.262 | L22: =+K22*H22 -> 61.699428 | M22: ='LABOR SHEET'!C$5 -> 57.65 | N22: =K22*M22 -> 15.1043 | O22: =M22*L22 -> 3556.972 | P22: =I22+N22 -> 22.3543 | Q22: =P22*H22 -> 5264.3035
A23: =IF(G23<>"",1+MAX($A$3:A22),"") -> 13 | D23: 2-1/2" Dia Gas Pipe | E23: 111.67 | F23: LF | G23: 0.05 | H23: =E23*(1+G23) -> 117.2535 | I23: 15.11 | J23: =I23*H23 -> 1771.7004 | K23: 0.32 | L23: =+K23*H23 -> 37.52112 | M23: ='LABOR SHEET'!C$5 -> 57.65 | N23: =K23*M23 -> 18.448 | O23: =M23*L23 -> 2163.0926 | P23: =I23+N23 -> 33.558 | Q23: =P23*H23 -> 3934.793
A24: =IF(G24<>"",1+MAX($A$3:A23),"") -> 14 | D24: 3" Dia Gas Pipe | E24: 193.04 | F24: LF | G24: 0.05 | H24: =E24*(1+G24) -> 202.692 | I24: =28.82/4*3 -> 21.615 | J24: =I24*H24 -> 4381.1876 | K24: 0.365 | L24: =+K24*H24 -> 73.98258 | M24: ='LABOR SHEET'!C$5 -> 57.65 | N24: =K24*M24 -> 21.04225 | O24: =M24*L24 -> 4265.0957 | P24: =I24+N24 -> 42.65725 | Q24: =P24*H24 -> 8646.2833
A25: =IF(G25<>"",1+MAX($A$3:A24),"") -> 15 | D25: 4" Dia Gas Pipe | E25: 66.58 | F25: LF | G25: 0.05 | H25: =E25*(1+G25) -> 69.909 | I25: 28.82 | J25: =I25*H25 -> 2014.7774 | K25: 0.444 | L25: =+K25*H25 -> 31.039596 | M25: ='LABOR SHEET'!C$5 -> 57.65 | N25: =K25*M25 -> 25.5966 | O25: =M25*L25 -> 1789.4327 | P25: =I25+N25 -> 54.4166 | Q25: =P25*H25 -> 3804.2101
A26: =IF(G26<>"",1+MAX($A$3:A25),"")
A27: =IF(G27<>"",1+MAX($A$3:A26),"") | D27: FITTINGS
A28: =IF(G28<>"",1+MAX($A$3:A27),"") -> 16 | D28: 3/4" Dia Gas Pipe 90 Deg Elbow | E28: 5 | F28: EA | G28: 0 | H28: =E28*(1+G28) -> 5 | I28: 4.59 | J28: =I28*H28 -> 22.95 | K28: 0.55 | L28: =+K28*H28 -> 2.75 | M28: ='LABOR SHEET'!C$5 -> 57.65 | N28: =K28*M28 -> 31.7075 | O28: =M28*L28 -> 158.5375 | P28: =I28+N28 -> 36.2975 | Q28: =P28*H28 -> 181.4875
A29: =IF(G29<>"",1+MAX($A$3:A28),"") -> 17 | D29: 1" Dia Gas Pipe 90 Deg Elbow | E29: 12 | F29: EA | G29: 0 | H29: =E29*(1+G29) -> 12 | I29: 8.5 | J29: =I29*H29 -> 102 | K29: 0.56 | L29: =+K29*H29 -> 6.72 | M29: ='LABOR SHEET'!C$5 -> 57.65 | N29: =K29*M29 -> 32.284 | O29: =M29*L29 -> 387.408 | P29: =I29+N29 -> 40.784 | Q29: =P29*H29 -> 489.408
A30: =IF(G30<>"",1+MAX($A$3:A29),"") -> 18 | D30: 1-1/4" Dia Gas Pipe 90 Deg Elbow | E30: 25 | F30: EA | G30: 0 | H30: =E30*(1+G30) -> 25 | I30: 9.1 | J30: =I30*H30 -> 227.5 | K30: 0.57 | L30: =+K30*H30 -> 14.25 | M30: ='LABOR SHEET'!C$5 -> 57.65 | N30: =K30*M30 -> 32.8605 | O30: =M30*L30 -> 821.5125 | P30: =I30+N30 -> 41.9605 | Q30: =P30*H30 -> 1049.0125
A31: =IF(G31<>"",1+MAX($A$3:A30),"") -> 19 | D31: 1-1/2" Dia Gas Pipe 90 Deg Elbow | E31: 1 | F31: EA | G31: 0 | H31: =E31*(1+G31) -> 1 | I31: 12.1 | J31: =I31*H31 -> 12.1 | K31: 0.58 | L31: =+K31*H31 -> 0.58 | M31: ='LABOR SHEET'!C$5 -> 57.65 | N31: =K31*M31 -> 33.437 | O31: =M31*L31 -> 33.437 | P31: =I31+N31 -> 45.537 | Q31: =P31*H31 -> 45.537
A32: =IF(G32<>"",1+MAX($A$3:A31),"") -> 20 | D32: 2" Dia Gas Pipe 90 Deg Elbow | E32: 5 | F32: EA | G32: 0 | H32: =E32*(1+G32) -> 5 | I32: 15.2 | J32: =I32*H32 -> 76 | K32: 0.59 | L32: =+K32*H32 -> 2.95 | M32: ='LABOR SHEET'!C$5 -> 57.65 | N32: =K32*M32 -> 34.0135 | O32: =M32*L32 -> 170.0675 | P32: =I32+N32 -> 49.2135 | Q32: =P32*H32 -> 246.0675
A33: =IF(G33<>"",1+MAX($A$3:A32),"") -> 21 | D33: 2-1/2" Dia Gas Pipe 90 Deg Elbow | E33: 4 | F33: EA | G33: 0 | H33: =E33*(1+G33) -> 4 | I33: 22.5 | J33: =I33*H33 -> 90 | K33: 0.6 | L33: =+K33*H33 -> 2.4 | M33: ='LABOR SHEET'!C$5 -> 57.65 | N33: =K33*M33 -> 34.59 | O33: =M33*L33 -> 138.36 | P33: =I33+N33 -> 57.09 | Q33: =P33*H33 -> 228.36
A34: =IF(G34<>"",1+MAX($A$3:A33),"") -> 22 | D34: 3" Dia Gas Pipe 90 Deg Elbow | E34: 2 | F34: EA | G34: 0 | H34: =E34*(1+G34) -> 2 | I34: 32.53 | J34: =I34*H34 -> 65.06 | K34: 0.61 | L34: =+K34*H34 -> 1.22 | M34: ='LABOR SHEET'!C$5 -> 57.65 | N34: =K34*M34 -> 35.1665 | O34: =M34*L34 -> 70.333 | P34: =I34+N34 -> 67.6965 | Q34: =P34*H34 -> 135.393
A35: =IF(G35<>"",1+MAX($A$3:A34),"") -> 23 | D35: 3/4" Dia Gas Pipe Tee | E35: 2 | F35: EA | G35: 0 | H35: =E35*(1+G35) -> 2 | I35: 6.45 | J35: =I35*H35 -> 12.9 | K35: 0.65 | L35: =+K35*H35 -> 1.3 | M35: ='LABOR SHEET'!C$5 -> 57.65 | N35: =K35*M35 -> 37.4725 | O35: =M35*L35 -> 74.945 | P35: =I35+N35 -> 43.9225 | Q35: =P35*H35 -> 87.845
A36: =IF(G36<>"",1+MAX($A$3:A35),"") -> 24 | D36: 1" Dia Gas Pipe Tee | E36: 4 | F36: EA | G36: 0 | H36: =E36*(1+G36) -> 4 | I36: 12.5 | J36: =I36*H36 -> 50 | K36: 0.67 | L36: =+K36*H36 -> 2.68 | M36: ='LABOR SHEET'!C$5 -> 57.65 | N36: =K36*M36 -> 38.6255 | O36: =M36*L36 -> 154.502 | P36: =I36+N36 -> 51.1255 | Q36: =P36*H36 -> 204.502
A37: =IF(G37<>"",1+MAX($A$3:A36),"") -> 25 | D37: 1-1/4" / 1" Dia Gas Pipe Tee | E37: 1 | F37: EA | G37: 0 | H37: =E37*(1+G37) -> 1 | I37: 18.25 | J37: =I37*H37 -> 18.25 | K37: 0.68 | L37: =+K37*H37 -> 0.68 | M37: ='LABOR SHEET'!C$5 -> 57.65 | N37: =K37*M37 -> 39.202 | O37: =M37*L37 -> 39.202 | P37: =I37+N37 -> 57.452 | Q37: =P37*H37 -> 57.452
A38: =IF(G38<>"",1+MAX($A$3:A37),"") -> 26 | D38: 1-1/4" Dia Gas Pipe Tee | E38: 7 | F38: EA | G38: 0 | H38: =E38*(1+G38) -> 7 | I38: 25.5 | J38: =I38*H38 -> 178.5 | K38: 0.69 | L38: =+K38*H38 -> 4.83 | M38: ='LABOR SHEET'!C$5 -> 57.65 | N38: =K38*M38 -> 39.7785 | O38: =M38*L38 -> 278.4495 | P38: =I38+N38 -> 65.2785 | Q38: =P38*H38 -> 456.9495
A39: =IF(G39<>"",1+MAX($A$3:A38),"") -> 27 | D39: 2" / 3/4" Dia Gas Pipe Tee | E39: 2 | F39: EA | G39: 0 | H39: =E39*(1+G39) -> 2 | I39: 30.5 | J39: =I39*H39 -> 61 | K39: 0.7 | L39: =+K39*H39 -> 1.4 | M39: ='LABOR SHEET'!C$5 -> 57.65 | N39: =K39*M39 -> 40.355 | O39: =M39*L39 -> 80.71 | P39: =I39+N39 -> 70.855 | Q39: =P39*H39 -> 141.71
... A56: =IF(G56<>"",1+MAX($A$3:A55),"") -> 44 | D56: 4" / 3" Dia Gas Pipe Reducer | E56: 1 | F56: EA | G56: 0 | H56: =E56*(1+G56) -> 1 | I56: 70.34 | J56: =I56*H56 -> 70.34 | K56: 0.53 | L56: =+K56*H56 -> 0.53 | M56: ='LABOR SHEET'!C$5 -> 57.65 | N56: =K56*M56 -> 30.5545 | O56: =M56*L56 -> 30.5545 | P56: =I56+N56 -> 100.8945 | Q56: =P56*H56 -> 100.8945
...

Sheet LABOR SHEET
B3: Labor Type | C3: Labor Rate
A5: Plumbing | B5: Plum | C5: 57.65
B9: Wastage
A10: Each/Count | B10: EA | C10: 0
A11: Linear Footage | B11: LF | C11: 0.05
A12: Square Footage | B12: SF | C12: 0.1
A13: Square Yard | B13: SY | C13: 0.1
A14: Cubic Yard | B14: CY | C14: 0.1
A15: Lumpsum | B15: LS | C15: 0
A16: Survery | B16: Survey | C16: 0
A17: Stair Riser | B17: RISER | C17: 0
A18: Blocks Count | B18: BLOCKS | C18: 0
A19: Bags of Pre-Mix Mortar | B19: BAGS | C19: 0
A20: Linear Footage of Wall | B20: LF.Wall | C20: 0.1
A21: Pounds | B21: LBS | C21: 0.1
... A32: N/A | B32: N/A | C32: 0
