Workbook

Sheet Takeoff Breakdown
A2: DETAILED BREAKDOWN OF ITEMS
B3: Project Name | D3: HERFF ROAD COMMERCIAL PHASE I IMPROVEMENTS
B4: Project Address | D4: 10-18 HERFF ROAD, BOERNE, TX 78006
B5: Scope: | D5: SITEWORK
A6: S# | B6: Dwg. | C6: CSI NO | D6: DESCRIPTION | E6: QTY. | F6: Wastage | G6: Qty w/ Waste | H6: UNIT | I6: UNIT LABOR HOUR | J6: TOTAL LABOR HOUR | K6: LABOR WAGE/ HOUR | L6: UNIT LABOR COST | M6: TOTAL LABOR COST | N6: UNIT MATERIAL COST | O6: TOTAL MATERIAL COST | P6: UNIT PRICE (Labor & Material) | Q6: TRADE TOTAL
C7: 1 | D7: DIVISION 01-GENERAL REQUIREMENTS
A8: =IF(F8<>"",1+MAX($A$2:A7),"") -> 1 | D8: Permits | E8: 1 | F8: 0 | G8: =(F8*E8)+E8 -> 1 | H8: LS | I8: 0 | J8: =+I8*G8 -> 0 | K8: 0 | L8: =I8*K8 -> 0 | M8: =K8*J8 -> 0 | N8: 0 | O8: =N8*G8 -> 0 | P8: =(I8*K8)+N8 -> 0 | Q8: 117000
A9: =IF(F9<>"",1+MAX($A$2:A8),"") -> 2 | D9: Supervision and Coordination | E9: 1 | F9: 0 | G9: =(F9*E9)+E9 -> 1 | H9: LS | I9: 0 | J9: =+I9*G9 -> 0 | K9: 0 | L9: =I9*K9 -> 0 | M9: =K9*J9 -> 0 | N9: 0 | O9: =N9*G9 -> 0 | P9: =(I9*K9)+N9 -> 0
A10: =IF(F10<>"",1+MAX($A$2:A9),"") -> 3 | D10: Submittals and Shop drawings | E10: 1 | F10: 0 | G10: =(F10*E10)+E10 -> 1 | H10: LS | I10: 0 | J10: =+I10*G10 -> 0 | K10: 0 | L10: =I10*K10 -> 0 | M10: =K10*J10 -> 0 | N10: 0 | O10: =N10*G10 -> 0 | P10: =(I10*K10)+N10 -> 0
A11: =IF(F11<>"",1+MAX($A$2:A10),"") -> 4 | D11: Final Cleaning | E11: 1 | F11: 0 | G11: =(F11*E11)+E11 -> 1 | H11: LS | I11: 0 | J11: =+I11*G11 -> 0 | K11: 0 | L11: =I11*K11 -> 0 | M11: =K11*J11 -> 0 | N11: 0 | O11: =N11*G11 -> 0 | P11: =(I11*K11)+N11 -> 0
A12: =IF(F12<>"",1+MAX($A$2:A11),"") -> 5 | D12: Mobilization Costs | E12: 1 | F12: 0 | G12: =(F12*E12)+E12 -> 1 | H12: LS | I12: 0 | J12: =+I12*G12 -> 0 | K12: 0 | L12: =I12*K12 -> 0 | M12: =K12*J12 -> 0 | N12: 0 | O12: =N12*G12 -> 0 | P12: =(I12*K12)+N12 -> 0
A13: =IF(F13<>"",1+MAX($A$2:A12),"") -> 6 | D13: Temporary Control & Facilities | E13: 1 | F13: 0 | G13: =(F13*E13)+E13 -> 1 | H13: LS | I13: 0 | J13: =+I13*G13 -> 0 | K13: 0 | L13: =I13*K13 -> 0 | M13: =K13*J13 -> 0 | N13: 0 | O13: =N13*G13 -> 0 | P13: =(I13*K13)+N13 -> 0
A14: =IF(F14<>"",1+MAX($A$2:A13),"") -> 7 | D14: Scaffolding | E14: 1 | F14: 0 | G14: =(F14*E14)+E14 -> 1 | H14: LS | I14: 0 | J14: =+I14*G14 -> 0 | K14: 0 | L14: =I14*K14 -> 0 | M14: =K14*J14 -> 0 | N14: 0 | O14: =N14*G14 -> 0 | P14: =(I14*K14)+N14 -> 0
A15: =IF(F15<>"",1+MAX($A$2:A14),"") | D15: SUBTOTAL | Q15: =SUM(Q8:Q14) -> 117000
A16: =IF(F16<>"",1+MAX($A$2:A15),"")
A17: =IF(F17<>"",1+MAX($A$2:A16),"") | C17: 2 | D17: DIVISION 02- EXISTING CONDITIONS
A18: =IF(F18<>"",1+MAX($A$2:A17),"") | D18: SITE DEMOLITION
A19: =IF(F19<>"",1+MAX($A$2:A18),"") -> 8 | B19: C2.0 | D19: Existing Structure To Be Removed | E19: 955 | F19: 0 | G19: =(F19*E19)+E19 -> 955 | H19: SF | I19: 0.028 | J19: =+I19*G19 -> 26.74 | K19: ='LABOR SHEET'!$C$5 -> 45 | L19: =I19*K19 -> 1.26 | M19: =K19*J19 -> 1203.3 | N19: 0 | O19: =N19*G19 -> 0 | P19: =(I19*K19)+N19 -> 1.26 | Q19: =P19*G19 -> 1203.3
A20: =IF(F20<>"",1+MAX($A$2:A19),"") -> 9 | D20: Existing Fence & Walls & Gate To Be Removed | E20: 355 | F20: 0 | G20: =(F20*E20)+E20 -> 355 | H20: LF | I20: 0.122 | J20: =+I20*G20 -> 43.31 | K20: ='LABOR SHEET'!$C$5 -> 45 | L20: =I20*K20 -> 5.49 | M20: =K20*J20 -> 1948.95 | N20: 0 | O20: =N20*G20 -> 0 | P20: =(I20*K20)+N20 -> 5.49 | Q20: =P20*G20 -> 1948.95
A21: =IF(F21<>"",1+MAX($A$2:A20),"") -> 10 | D21: Existing Side Walk To Be Removed | E21: 675 | F21: 0 | G21: =(F21*E21)+E21 -> 675 | H21: SF | I21: 0.024 | J21: =+I21*G21 -> 16.2 | K21: ='LABOR SHEET'!$C$5 -> 45 | L21: =I21*K21 -> 1.08 | M21: =K21*J21 -> 729 | N21: 0 | O21: =N21*G21 -> 0 | P21: =(I21*K21)+N21 -> 1.08 | Q21: =P21*G21 -> 729
A22: =IF(F22<>"",1+MAX($A$2:A21),"") -> 11 | D22: Existing Wire Fence To Be Removed | E22: 636 | F22: 0 | G22: =(F22*E22)+E22 -> 636 | H22: LF | I22: 0.1 | J22: =+I22*G22 -> 63.6 | K22: ='LABOR SHEET'!$C$5 -> 45 | L22: =I22*K22 -> 4.5 | M22: =K22*J22 -> 2862 | N22: 0 | O22: =N22*G22 -> 0 | P22: =(I22*K22)+N22 -> 4.5 | Q22: =P22*G22 -> 2862
A23: =IF(F23<>"",1+MAX($A$2:A22),"") -> 12 | D23: Existing Asphalt Pavement To Be Removed | E23: 7205 | F23: 0 | G23: =(F23*E23)+E23 -> 7205 | H23: SF | I23: 0.028 | J23: =+I23*G23 -> 201.74 | K23: ='LABOR SHEET'!$C$5 -> 45 | L23: =I23*K23 -> 1.26 | M23: =K23*J23 -> 9078.3 | N23: 0 | O23: =N23*G23 -> 0 | P23: =(I23*K23)+N23 -> 1.26 | Q23: =P23*G23 -> 9078.3
A24: =IF(F24<>"",1+MAX($A$2:A23),"") -> 13 | D24: Sawcut For Pavement Removal | E24: 49 | F24: 0 | G24: =(F24*E24)+E24 -> 49 | H24: LF | I24: 0.045 | J24: =+I24*G24 -> 2.205 | K24: ='LABOR SHEET'!$C$5 -> 45 | L24: =I24*K24 -> 2.025 | M24: =K24*J24 -> 99.225 | N24: 0 | O24: =N24*G24 -> 0 | P24: =(I24*K24)+N24 -> 2.025 | Q24: =P24*G24 -> 99.225
A26: =IF(F26<>"",1+MAX($A$2:A24),"") | D26: Landscaping Demolition | M26: =K26*J26 -> 0
A27: =IF(F27<>"",1+MAX($A$2:A26),"") -> 14 | D27: Existing Oak Trees To Be Removed | E27: =44*2 -> 88 | F27: 0 | G27: =(F27*E27)+E27 -> 88 | H27: EA | I27: 2.85 | J27: =+I27*G27 -> 250.8 | K27: ='LABOR SHEET'!$C$5 -> 45 | L27: =I27*K27 -> 128.25 | M27: =K27*J27 -> 11286 | N27: 0 | O27: =N27*G27 -> 0 | P27: =(I27*K27)+N27 -> 128.25 | Q27: =P27*G27 -> 11286
A28: =IF(F28<>"",1+MAX($A$2:A27),"") -> 15 | D28: Existing Oak Trees To Be Removed | E28: 41 | F28: 0 | G28: =(F28*E28)+E28 -> 41 | H28: EA | I28: 2.85 | J28: =+I28*G28 -> 116.85 | K28: ='LABOR SHEET'!$C$5 -> 45 | L28: =I28*K28 -> 128.25 | M28: =K28*J28 -> 5258.25 | N28: 0 | O28: =N28*G28 -> 0 | P28: =(I28*K28)+N28 -> 128.25 | Q28: =P28*G28 -> 5258.25
A29: =IF(F29<>"",1+MAX($A$2:A28),"") -> 16 | D29: Existing Oak Trees To Be Removed | E29: 53 | F29: 0 | G29: =(F29*E29)+E29 -> 53 | H29: EA | I29: 2.85 | J29: =+I29*G29 -> 151.05 | K29: ='LABOR SHEET'!$C$5 -> 45 | L29: =I29*K29 -> 128.25 | M29: =K29*J29 -> 6797.25 | N29: 0 | O29: =N29*G29 -> 0 | P29: =(I29*K29)+N29 -> 128.25 | Q29: =P29*G29 -> 6797.25
A30: =IF(F30<>"",1+MAX($A$2:A29),"") -> 17 | D30: Existing Oak Trees To Be Removed | E30: 50 | F30: 0 | G30: =(F30*E30)+E30 -> 50 | H30: EA | I30: 2.85 | J30: =+I30*G30 -> 142.5 | K30: ='LABOR SHEET'!$C$5 -> 45 | L30: =I30*K30 -> 128.25 | M30: =K30*J30 -> 6412.5 | N30: 0 | O30: =N30*G30 -> 0 | P30: =(I30*K30)+N30 -> 128.25 | Q30: =P30*G30 -> 6412.5
A31: =IF(F31<>"",1+MAX($A$2:A30),"") -> 18 | D31: Existing Oak Trees To Be Removed | E31: 49 | F31: 0 | G31: =(F31*E31)+E31 -> 49 | H31: EA | I31: 2.85 | J31: =+I31*G31 -> 139.65 | K31: ='LABOR SHEET'!$C$5 -> 45 | L31: =I31*K31 -> 128.25 | M31: =K31*J31 -> 6284.25 | N31: 0 | O31: =N31*G31 -> 0 | P31: =(I31*K31)+N31 -> 128.25 | Q31: =P31*G31 -> 6284.25
A32: =IF(F32<>"",1+MAX($A$2:A31),"") -> 19 | D32: Existing Oak Trees To Be Removed | E32: 61 | F32: 0 | G32: =(F32*E32)+E32 -> 61 | H32: EA | I32: 2.85 | J32: =+I32*G32 -> 173.85 | K32: ='LABOR SHEET'!$C$5 -> 45 | L32: =I32*K32 -> 128.25 | M32: =K32*J32 -> 7823.25 | N32: 0 | O32: =N32*G32 -> 0 | P32: =(I32*K32)+N32 -> 128.25 | Q32: =P32*G32 -> 7823.25
A33: =IF(F33<>"",1+MAX($A$2:A32),"") -> 20 | D33: Existing Oak Trees To Be Removed | E33: =90+1401 -> 1491 | F33: 0 | G33: =(F33*E33)+E33 -> 1491 | H33: EA | I33: 2.85 | J33: =+I33*G33 -> 4249.35 | K33: ='LABOR SHEET'!$C$5 -> 45 | L33: =I33*K33 -> 128.25 | M33: =K33*J33 -> 191220.75 | N33: 0 | O33: =N33*G33 -> 0 | P33: =(I33*K33)+N33 -> 128.25 | Q33: =P33*G33 -> 191220.75
A34: =IF(F34<>"",1+MAX($A$2:A33),"") -> 21 | D34: Existing Pecan Trees To Be Removed | E34: 50 | F34: 0 | G34: =(F34*E34)+E34 -> 50 | H34: EA | I34: 2.85 | J34: =+I34*G34 -> 142.5 | K34: ='LABOR SHEET'!$C$5 -> 45 | L34: =I34*K34 -> 128.25 | M34: =K34*J34 -> 6412.5 | N34: 0 | O34: =N34*G34 -> 0 | P34: =(I34*K34)+N34 -> 128.25 | Q34: =P34*G34 -> 6412.5
A36: =IF(F36<>"",1+MAX($A$2:A34),"") -> 22 | D36: Hauling Of demolation Materials | E36: 1 | F36: 0 | G36: =(F36*E36)+E36 -> 1 | H36: LS | I36: 0 | J36: =+I36*G36 -> 0 | K36: ='LABOR SHEET'!$C$5 -> 45 | L36: =I36*K36 -> 0 | M36: =K36*J36 -> 0 | N36: =1250*4 -> 5000 | O36: =N36*G36 -> 5000 | P36: =(I36*K36)+N36 -> 5000 | Q36: =P36*G36 -> 5000
A37: =IF(F37<>"",1+MAX($A$2:A36),"") | D37: SUBTOTAL | Q37: =SUM(Q19:Q36) -> 262415.53
A38: =IF(F38<>"",1+MAX($A$2:A37),"")
A39: =IF(F39<>"",1+MAX($A$2:A38),"") | C39: 31 | D39: DIVISION 31- EARTHWORK
A40: =IF(F40<>"",1+MAX($A$2:A39),"") | D40: GRADING
A41: =IF(F41<>"",1+MAX($A$2:A40),"") -> 23 | B41: C2.0-C9 | D41: Total Cut | E41: 1685.98 | F41: 0 | G41: =E41*(1+F41) -> 1685.98 | H41: CY | I41: 0.22 | J41: =+I41*G41 -> 370.9156 | K41: ='LABOR SHEET'!$C$4 -> 45 | L41: =I41*K41 -> 9.9 | M41: =K41*J41 -> 16691.202 | N41: 5 | O41: =N41*G41 -> 8429.9 | P41: =(I41*K41)+N41 -> 14.9 | Q41: =P41*G41 -> 25121.102
A42: =IF(F42<>"",1+MAX($A$2:A41),"") -> 24 | D42: Total Fill | E42: 6718.51 | F42: 0 | G42: =E42*(1+F42) -> 6718.51 | H42: CY | I42: 0.2 | J42: =+I42*G42 -> 1343.702 | K42: ='LABOR SHEET'!$C$4 -> 45 | L42: =I42*K42 -> 9 | M42: =K42*J42 -> 60466.59 | N42: 5 | O42: =N42*G42 -> 33592.55 | P42: =(I42*K42)+N42 -> 14 | Q42: =P42*G42 -> 94059.14
A43: =IF(F43<>"",1+MAX($A$2:A42),"") -> 25 | D43: Soil To Be Import | E43: =6718.51-1685.98-1475+704 -> 4261.53 | F43: 0 | G43: =E43*(1+F43) -> 4261.53 | H43: CY | I43: 0.44 | J43: =+I43*G43 -> 1875.0732 | K43: ='LABOR SHEET'!$C$4 -> 45 | L43: =I43*K43 -> 19.8 | M43: =K43*J43 -> 84378.294 | N43: 10 | O43: =N43*G43 -> 42615.3 | P43: =(I43*K43)+N43 -> 29.8 | Q43: =P43*G43 -> 126993.59
...

Sheet LABOR SHEET
B1: Labor Type | C1: Labor Rate
A3: Plumbing | B3: Plum | C3: 70
A4: Earthwork | B4: Q14C | C4: 45
A5: Exterior Improvement | B5: B15S | C5: 45
A8: Manhour Increase Factor | B8: 0
B10: Wastage
A11: Each/Count | B11: EA | C11: 0
A12: Linear Footage | B12: LF | C12: 0.05
A13: Square Footage | B13: SF | C13: 0.1
A14: Square Yard | B14: SY | C14: 0.1
A15: Cubic Yard | B15: CY | C15: 0.1
A16: Lumpsum | B16: LS | C16: 0
A17: Survery | B17: Survey | C17: 0
A18: Stair Riser | B18: RISER | C18: 0
A19: Blocks Count | B19: BLOCKS | C19: 0
A20: Bags of Pre-Mix Mortar | B20: BAGS | C20: 0
A21: Linear Footage of Wall | B21: LF.Wall | C21: 0.1
A22: Pounds | B22: LBS | C22: 0.1
... A33: N/A | B33: N/A | C33: 0
A36: NOTE:
A37: Prevailing wages have been included in this estimate in compliance with the Davis-Bacon Act.
A38: Material pricing is based on current market rates sourced from reputable online platforms and suppliers.
A39: Please note that actual costs may vary depending on site-specific conditions, unforeseen circumstances, or changes in market conditions.
